2019-10-24T12:28:48|CRITICAL|root|Unhandled exception:Traceback (most recent call last):
  File "C:\ProgramData\Anaconda3\lib\site-packages\ScopeFoundry\hardware.py", line 208, in enable_connection
    raise err
  File "C:\ProgramData\Anaconda3\lib\site-packages\ScopeFoundry\hardware.py", line 204, in enable_connection
    self.connect()
  File "C:\LabPrograms\Python\laser\laser_hardware.py", line 35, in connect
    self.laser = LaserDevice(port=self.port.val, debug=self.debug_mode.val)
  File "C:\LabPrograms\Python\laser\laser_device.py", line 16, in __init__
    stopbits=1, xonxoff=False, timeout=3.0)
  File "C:\ProgramData\Anaconda3\lib\site-packages\serial\serialwin32.py", line 31, in __init__
    super(Serial, self).__init__(*args, **kwargs)
  File "C:\ProgramData\Anaconda3\lib\site-packages\serial\serialutil.py", line 240, in __init__
    self.open()
  File "C:\ProgramData\Anaconda3\lib\site-packages\serial\serialwin32.py", line 62, in open
    raise SerialException("could not open port {!r}: {!r}".format(self.portstr, ctypes.WinError()))
serial.serialutil.SerialException: could not open port 'COM7': PermissionError(13, 'Accesso negato.', None, 5)

2019-10-24T12:28:48|CRITICAL|root|Unhandled exception:Traceback (most recent call last):
  File "C:\ProgramData\Anaconda3\lib\site-packages\ScopeFoundry\hardware.py", line 208, in enable_connection
    raise err
  File "C:\ProgramData\Anaconda3\lib\site-packages\ScopeFoundry\hardware.py", line 204, in enable_connection
    self.connect()
  File "C:\LabPrograms\Python\laser\laser_hardware.py", line 35, in connect
    self.laser = LaserDevice(port=self.port.val, debug=self.debug_mode.val)
  File "C:\LabPrograms\Python\laser\laser_device.py", line 16, in __init__
    stopbits=1, xonxoff=False, timeout=3.0)
  File "C:\ProgramData\Anaconda3\lib\site-packages\serial\serialwin32.py", line 31, in __init__
    super(Serial, self).__init__(*args, **kwargs)
  File "C:\ProgramData\Anaconda3\lib\site-packages\serial\serialutil.py", line 240, in __init__
    self.open()
  File "C:\ProgramData\Anaconda3\lib\site-packages\serial\serialwin32.py", line 62, in open
    raise SerialException("could not open port {!r}: {!r}".format(self.portstr, ctypes.WinError()))
serial.serialutil.SerialException: could not open port 'COM7': PermissionError(13, 'Accesso negato.', None, 5)

2019-10-24T12:34:09|CRITICAL|root|Unhandled exception:Traceback (most recent call last):
  File "C:\ProgramData\Anaconda3\lib\site-packages\ScopeFoundry\measurement.py", line 244, in start_stop
    self._start()
  File "C:\ProgramData\Anaconda3\lib\site-packages\ScopeFoundry\measurement.py", line 134, in _start
    raise RuntimeError("Cannot start a new measurement while still measuring")
RuntimeError: Cannot start a new measurement while still measuring

2019-10-24T12:51:14|CRITICAL|root|Unhandled exception:Traceback (most recent call last):
  File "C:\ProgramData\Anaconda3\lib\site-packages\h5py\_hl\files.py", line 162, in make_fid
    fid = h5f.open(name, h5f.ACC_RDWR, fapl=fapl)
  File "h5py\_objects.pyx", line 54, in h5py._objects.with_phil.wrapper
  File "h5py\_objects.pyx", line 55, in h5py._objects.with_phil.wrapper
  File "h5py\h5f.pyx", line 78, in h5py.h5f.open
OSError: Unable to open file (unable to open file: name = 'D:/Data/24.10 nanobeats h2o/h20\191024_125108_SyncreadoutTriggerMeasurement.h5', errno = 2, error message = 'No such file or directory', flags = 1, o_flags = 2)

During handling of the above exception, another exception occurred:

Traceback (most recent call last):
  File "C:\ProgramData\Anaconda3\lib\site-packages\h5py\_hl\files.py", line 165, in make_fid
    fid = h5f.open(name, h5f.ACC_RDONLY, fapl=fapl)
  File "h5py\_objects.pyx", line 54, in h5py._objects.with_phil.wrapper
  File "h5py\_objects.pyx", line 55, in h5py._objects.with_phil.wrapper
  File "h5py\h5f.pyx", line 78, in h5py.h5f.open
OSError: Unable to open file (unable to open file: name = 'D:/Data/24.10 nanobeats h2o/h20\191024_125108_SyncreadoutTriggerMeasurement.h5', errno = 2, error message = 'No such file or directory', flags = 0, o_flags = 0)

During handling of the above exception, another exception occurred:

Traceback (most recent call last):
  File "C:\ProgramData\Anaconda3\lib\site-packages\ScopeFoundry\measurement.py", line 25, in run
    self.measurement._thread_run()
  File "C:\ProgramData\Anaconda3\lib\site-packages\ScopeFoundry\measurement.py", line 179, in _thread_run
    self.run()
  File "C:\LabPrograms\Python\DAQ-Laser-Camera\SyncreadoutTriggerMeasurement.py", line 169, in run
    self.initH5()
  File "C:\LabPrograms\Python\Hamamatsu_ScopeFoundry\CameraMeasurement.py", line 286, in initH5
    self.h5file = h5_io.h5_base_file(app=self.app, measurement=self)
  File "C:\ProgramData\Anaconda3\lib\site-packages\ScopeFoundry\h5_io.py", line 65, in h5_base_file
    h5_file = h5py.File(fname)
  File "C:\ProgramData\Anaconda3\lib\site-packages\h5py\_hl\files.py", line 312, in __init__
    fid = make_fid(name, mode, userblock_size, fapl, swmr=swmr)
  File "C:\ProgramData\Anaconda3\lib\site-packages\h5py\_hl\files.py", line 167, in make_fid
    fid = h5f.create(name, h5f.ACC_EXCL, fapl=fapl, fcpl=fcpl)
  File "h5py\_objects.pyx", line 54, in h5py._objects.with_phil.wrapper
  File "h5py\_objects.pyx", line 55, in h5py._objects.with_phil.wrapper
  File "h5py\h5f.pyx", line 98, in h5py.h5f.create
OSError: Unable to create file (unable to open file: name = 'D:/Data/24.10 nanobeats h2o/h20\191024_125108_SyncreadoutTriggerMeasurement.h5', errno = 2, error message = 'No such file or directory', flags = 15, o_flags = 502)

2019-10-24T12:52:32|CRITICAL|root|Unhandled exception:Traceback (most recent call last):
  File "C:\ProgramData\Anaconda3\lib\site-packages\h5py\_hl\files.py", line 162, in make_fid
    fid = h5f.open(name, h5f.ACC_RDWR, fapl=fapl)
  File "h5py\_objects.pyx", line 54, in h5py._objects.with_phil.wrapper
  File "h5py\_objects.pyx", line 55, in h5py._objects.with_phil.wrapper
  File "h5py\h5f.pyx", line 78, in h5py.h5f.open
OSError: Unable to open file (unable to open file: name = 'D:/Data/24.10 nanobeats h2o/h20\191024_125225_SyncreadoutTriggerMeasurement.h5', errno = 2, error message = 'No such file or directory', flags = 1, o_flags = 2)

During handling of the above exception, another exception occurred:

Traceback (most recent call last):
  File "C:\ProgramData\Anaconda3\lib\site-packages\h5py\_hl\files.py", line 165, in make_fid
    fid = h5f.open(name, h5f.ACC_RDONLY, fapl=fapl)
  File "h5py\_objects.pyx", line 54, in h5py._objects.with_phil.wrapper
  File "h5py\_objects.pyx", line 55, in h5py._objects.with_phil.wrapper
  File "h5py\h5f.pyx", line 78, in h5py.h5f.open
OSError: Unable to open file (unable to open file: name = 'D:/Data/24.10 nanobeats h2o/h20\191024_125225_SyncreadoutTriggerMeasurement.h5', errno = 2, error message = 'No such file or directory', flags = 0, o_flags = 0)

During handling of the above exception, another exception occurred:

Traceback (most recent call last):
  File "C:\ProgramData\Anaconda3\lib\site-packages\ScopeFoundry\measurement.py", line 25, in run
    self.measurement._thread_run()
  File "C:\ProgramData\Anaconda3\lib\site-packages\ScopeFoundry\measurement.py", line 179, in _thread_run
    self.run()
  File "C:\LabPrograms\Python\DAQ-Laser-Camera\SyncreadoutTriggerMeasurement.py", line 169, in run
    self.initH5()
  File "C:\LabPrograms\Python\Hamamatsu_ScopeFoundry\CameraMeasurement.py", line 286, in initH5
    self.h5file = h5_io.h5_base_file(app=self.app, measurement=self)
  File "C:\ProgramData\Anaconda3\lib\site-packages\ScopeFoundry\h5_io.py", line 65, in h5_base_file
    h5_file = h5py.File(fname)
  File "C:\ProgramData\Anaconda3\lib\site-packages\h5py\_hl\files.py", line 312, in __init__
    fid = make_fid(name, mode, userblock_size, fapl, swmr=swmr)
  File "C:\ProgramData\Anaconda3\lib\site-packages\h5py\_hl\files.py", line 167, in make_fid
    fid = h5f.create(name, h5f.ACC_EXCL, fapl=fapl, fcpl=fcpl)
  File "h5py\_objects.pyx", line 54, in h5py._objects.with_phil.wrapper
  File "h5py\_objects.pyx", line 55, in h5py._objects.with_phil.wrapper
  File "h5py\h5f.pyx", line 98, in h5py.h5f.create
OSError: Unable to create file (unable to open file: name = 'D:/Data/24.10 nanobeats h2o/h20\191024_125225_SyncreadoutTriggerMeasurement.h5', errno = 2, error message = 'No such file or directory', flags = 15, o_flags = 502)

