2019-11-27T18:12:21|CRITICAL|root|Unhandled exception:Traceback (most recent call last):
  File "C:\LabPrograms\Python\Hamamatsu_ScopeFoundry\CameraMeasurement.py", line 108, in run
    self.initH5()
  File "C:\LabPrograms\Python\Hamamatsu_ScopeFoundry\CameraMeasurement.py", line 296, in initH5
    self.h5file = h5_io.h5_base_file(app=self.app, measurement=self, fname = fnam + self.app.settings['sample'])
NameError: name 'fnam' is not defined

During handling of the above exception, another exception occurred:

Traceback (most recent call last):
  File "C:\ProgramData\Anaconda3\lib\site-packages\ScopeFoundry\measurement.py", line 25, in run
    self.measurement._thread_run()
  File "C:\ProgramData\Anaconda3\lib\site-packages\ScopeFoundry\measurement.py", line 179, in _thread_run
    self.run()
  File "C:\LabPrograms\Python\Hamamatsu_ScopeFoundry\CameraMeasurement.py", line 239, in run
    self.h5file.close() # close h5 file
AttributeError: 'HamamatsuMeasurement' object has no attribute 'h5file'

