2019-02-08T15:21:28|CRITICAL|root|Unhandled exception:Traceback (most recent call last):
  File "C:\ProgramData\Anaconda3\lib\site-packages\h5py\_hl\files.py", line 162, in make_fid
    fid = h5f.open(name, h5f.ACC_RDWR, fapl=fapl)
  File "h5py\_objects.pyx", line 54, in h5py._objects.with_phil.wrapper
  File "h5py\_objects.pyx", line 55, in h5py._objects.with_phil.wrapper
  File "h5py\h5f.pyx", line 78, in h5py.h5f.open
OSError: Unable to open file (unable to open file: name = 'E:\data\DMD\190208_152125_hamamatsu_image.h5', errno = 13, error message = 'Permission denied', flags = 1, o_flags = 2)

During handling of the above exception, another exception occurred:

Traceback (most recent call last):
  File "C:\ProgramData\Anaconda3\lib\site-packages\h5py\_hl\files.py", line 165, in make_fid
    fid = h5f.open(name, h5f.ACC_RDONLY, fapl=fapl)
  File "h5py\_objects.pyx", line 54, in h5py._objects.with_phil.wrapper
  File "h5py\_objects.pyx", line 55, in h5py._objects.with_phil.wrapper
  File "h5py\h5f.pyx", line 78, in h5py.h5f.open
OSError: Unable to open file (unable to open file: name = 'E:\data\DMD\190208_152125_hamamatsu_image.h5', errno = 13, error message = 'Permission denied', flags = 0, o_flags = 0)

During handling of the above exception, another exception occurred:

Traceback (most recent call last):
  File "C:\Users\Admin\eclipse-workspace\Laser_DAQ_Camera\DaqControlledMeasurement.py", line 159, in run
    self.initH5()
  File "C:\Users\Admin\eclipse-workspace\Laser_DAQ_Camera\DaqControlledMeasurement.py", line 330, in initH5
    self.h5file = h5_io.h5_base_file(app=self.app, measurement=self)
  File "C:\ProgramData\Anaconda3\lib\site-packages\ScopeFoundry\h5_io.py", line 65, in h5_base_file
    h5_file = h5py.File(fname)
  File "C:\ProgramData\Anaconda3\lib\site-packages\h5py\_hl\files.py", line 312, in __init__
    fid = make_fid(name, mode, userblock_size, fapl, swmr=swmr)
  File "C:\ProgramData\Anaconda3\lib\site-packages\h5py\_hl\files.py", line 167, in make_fid
    fid = h5f.create(name, h5f.ACC_EXCL, fapl=fapl, fcpl=fcpl)
  File "h5py\_objects.pyx", line 54, in h5py._objects.with_phil.wrapper
  File "h5py\_objects.pyx", line 55, in h5py._objects.with_phil.wrapper
  File "h5py\h5f.pyx", line 98, in h5py.h5f.create
OSError: Unable to create file (unable to open file: name = 'E:\data\DMD\190208_152125_hamamatsu_image.h5', errno = 13, error message = 'Permission denied', flags = 15, o_flags = 502)

During handling of the above exception, another exception occurred:

Traceback (most recent call last):
  File "C:\ProgramData\Anaconda3\lib\site-packages\ScopeFoundry\measurement.py", line 25, in run
    self.measurement._thread_run()
  File "C:\ProgramData\Anaconda3\lib\site-packages\ScopeFoundry\measurement.py", line 179, in _thread_run
    self.run()
  File "C:\Users\Admin\eclipse-workspace\Laser_DAQ_Camera\DaqControlledMeasurement.py", line 242, in run
    self.h5file.close() # close h5 file
AttributeError: 'DaqControlledMeasurement' object has no attribute 'h5file'

