2020-07-20T16:48:17|CRITICAL|root|Unhandled exception:Traceback (most recent call last):
  File "C:\LabPrograms\Python\DAQ_Laser_Camera\Laser_DAQ_Camera_App.py", line 50, in <module>
    app = Laser_DAQ_Camera_App(sys.argv)
  File "C:\LabPrograms\Python\BaseMicroscopeModified_ScopeFoundry\BaseMicroscopeAppModified.py", line 16, in __init__
    super().__init__(*kwds) # *kwds is needed since in the main we pass as argument sys.argv. Without
  File "C:\ProgramData\Anaconda3\lib\site-packages\ScopeFoundry\base_app.py", line 332, in __init__
    self.setup()
  File "C:\LabPrograms\Python\DAQ_Laser_Camera\Laser_DAQ_Camera_App.py", line 20, in setup
    self.add_hardware(ElveflowHardware(self))
TypeError: 'module' object is not callable

