2019-02-07T17:25:55|CRITICAL|root|Unhandled exception:Traceback (most recent call last):
  File "C:\ProgramData\Anaconda3\lib\site-packages\ScopeFoundry\measurement.py", line 25, in run
    self.measurement._thread_run()
  File "C:\ProgramData\Anaconda3\lib\site-packages\ScopeFoundry\measurement.py", line 179, in _thread_run
    self.run()
  File "C:\Users\Admin\eclipse-workspace\Laser_DAQ_Camera\DaqControlledMeasurement.py", line 60, in run
    self.set_all_parameters()
  File "C:\Users\Admin\eclipse-workspace\Laser_DAQ_Camera\DaqControlledMeasurement.py", line 210, in set_all_parameters
    for lq in self.laser.settings:
  File "C:\ProgramData\Anaconda3\lib\site-packages\ScopeFoundry\logged_quantity.py", line 1148, in __getitem__
    return self._logged_quantities[key].val
KeyError: 0

