2020-07-20T17:16:11|CRITICAL|root|Unhandled exception:Traceback (most recent call last):
  File "C:\ProgramData\Anaconda3\lib\site-packages\ScopeFoundry\hardware.py", line 208, in enable_connection
    raise err
  File "C:\ProgramData\Anaconda3\lib\site-packages\ScopeFoundry\hardware.py", line 204, in enable_connection
    self.connect()
  File "C:\LabPrograms\Python\ElveflowScopeFoundry\ElveflowHardware.py", line 55, in connect
    calibration_kind = "default")
  File "C:\LabPrograms\Python\ElveflowScopeFoundry\ElveflowDevice.py", line 76, in __init__
    reg_ch_4=Z_REGULATOR_TYPE_M1000_1000_MBAR)
  File "C:\LabPrograms\Python\ElveflowScopeFoundry\ElveflowDevice.py", line 107, in initElveflow
    self.checkError(error)
  File "C:\LabPrograms\Python\ElveflowScopeFoundry\ElveflowDevice.py", line 94, in checkError
    print("Error number ", error, ": " ,error_dict[error])
KeyError: -301706

