2019-06-04T15:48:08|CRITICAL|root|Unhandled exception:Traceback (most recent call last):
  File "C:\ProgramData\Anaconda3\lib\site-packages\ScopeFoundry\measurement.py", line 25, in run
    self.measurement._thread_run()
  File "C:\ProgramData\Anaconda3\lib\site-packages\ScopeFoundry\measurement.py", line 179, in _thread_run
    self.run()
  File "C:\LabPrograms\Python\DAQ-Laser-Camera\temp_measurement.py", line 85, in run
    self.initH5()
  File "C:\LabPrograms\Python\DAQ-Laser-Camera\temp_measurement.py", line 115, in initH5
    length=self.camera.number_image_on_the_run.val
AttributeError: 'HamamatsuHardware' object has no attribute 'number_image_on_the_run'

