2019-02-06T11:39:31|CRITICAL|root|Unhandled exception:Traceback (most recent call last):
  File "C:\ProgramData\Anaconda3\lib\site-packages\ScopeFoundry\measurement.py", line 25, in run
    self.measurement._thread_run()
  File "C:\ProgramData\Anaconda3\lib\site-packages\ScopeFoundry\measurement.py", line 179, in _thread_run
    self.run()
  File "C:\Users\Admin\eclipse-workspace\Laser_DAQ_Camera\DaqControlledMeasurement.py", line 27, in run
    self.ni.write_value()
  File "C:\LabPrograms\Python\nidaqmx_test\ni_do_hardware.py", line 46, in write_value
    self.DO_device.write(self.value.val)
AttributeError: 'int' object has no attribute 'val'

