2019-12-03T09:53:14|CRITICAL|root|Unhandled exception:Traceback (most recent call last):
  File "C:\ProgramData\Anaconda3\lib\site-packages\ScopeFoundry\hardware.py", line 208, in enable_connection
    raise err
  File "C:\ProgramData\Anaconda3\lib\site-packages\ScopeFoundry\hardware.py", line 204, in enable_connection
    self.connect()
  File "C:\LabPrograms\Python\Hamamatsu_ScopeFoundry\CameraHardware.py", line 115, in connect
    binning = self.binning.val, hardware = self) #maybe with more cameras we have to change
  File "C:\LabPrograms\Python\Hamamatsu_ScopeFoundry\CameraDevice.py", line 336, in __init__
    raise DCAMException("DCAM initialization failed with error code " + str(error_code))
CameraDevice.DCAMException: DCAM initialization failed with error code -2147483130

2019-12-03T09:53:31|CRITICAL|root|Unhandled exception:Traceback (most recent call last):
  File "C:\ProgramData\Anaconda3\lib\site-packages\ScopeFoundry\hardware.py", line 208, in enable_connection
    raise err
  File "C:\ProgramData\Anaconda3\lib\site-packages\ScopeFoundry\hardware.py", line 204, in enable_connection
    self.connect()
  File "C:\LabPrograms\Python\laser\laser_hardware.py", line 35, in connect
    self.laser = LaserDevice(port=self.port.val, debug=self.debug_mode.val)
  File "C:\LabPrograms\Python\laser\laser_device.py", line 16, in __init__
    stopbits=1, xonxoff=False, timeout=3.0)
  File "C:\ProgramData\Anaconda3\lib\site-packages\serial\serialwin32.py", line 31, in __init__
    super(Serial, self).__init__(*args, **kwargs)
  File "C:\ProgramData\Anaconda3\lib\site-packages\serial\serialutil.py", line 240, in __init__
    self.open()
  File "C:\ProgramData\Anaconda3\lib\site-packages\serial\serialwin32.py", line 62, in open
    raise SerialException("could not open port {!r}: {!r}".format(self.portstr, ctypes.WinError()))
serial.serialutil.SerialException: could not open port 'COM7': PermissionError(13, 'Accesso negato.', None, 5)

2019-12-03T09:53:46|CRITICAL|root|Unhandled exception:Traceback (most recent call last):
  File "C:\ProgramData\Anaconda3\lib\site-packages\ScopeFoundry\hardware.py", line 208, in enable_connection
    raise err
  File "C:\ProgramData\Anaconda3\lib\site-packages\ScopeFoundry\hardware.py", line 204, in enable_connection
    self.connect()
  File "C:\LabPrograms\Python\Hamamatsu_ScopeFoundry\CameraHardware.py", line 115, in connect
    binning = self.binning.val, hardware = self) #maybe with more cameras we have to change
  File "C:\LabPrograms\Python\Hamamatsu_ScopeFoundry\CameraDevice.py", line 336, in __init__
    raise DCAMException("DCAM initialization failed with error code " + str(error_code))
CameraDevice.DCAMException: DCAM initialization failed with error code -2147483130

2019-12-03T09:53:48|CRITICAL|root|Unhandled exception:Traceback (most recent call last):
  File "C:\ProgramData\Anaconda3\lib\site-packages\ScopeFoundry\hardware.py", line 208, in enable_connection
    raise err
  File "C:\ProgramData\Anaconda3\lib\site-packages\ScopeFoundry\hardware.py", line 204, in enable_connection
    self.connect()
  File "C:\LabPrograms\Python\Hamamatsu_ScopeFoundry\CameraHardware.py", line 115, in connect
    binning = self.binning.val, hardware = self) #maybe with more cameras we have to change
  File "C:\LabPrograms\Python\Hamamatsu_ScopeFoundry\CameraDevice.py", line 336, in __init__
    raise DCAMException("DCAM initialization failed with error code " + str(error_code))
CameraDevice.DCAMException: DCAM initialization failed with error code -2147483130

2019-12-03T09:53:53|CRITICAL|root|Unhandled exception:Traceback (most recent call last):
  File "C:\ProgramData\Anaconda3\lib\site-packages\ScopeFoundry\hardware.py", line 208, in enable_connection
    raise err
  File "C:\ProgramData\Anaconda3\lib\site-packages\ScopeFoundry\hardware.py", line 204, in enable_connection
    self.connect()
  File "C:\LabPrograms\Python\Hamamatsu_ScopeFoundry\CameraHardware.py", line 115, in connect
    binning = self.binning.val, hardware = self) #maybe with more cameras we have to change
  File "C:\LabPrograms\Python\Hamamatsu_ScopeFoundry\CameraDevice.py", line 336, in __init__
    raise DCAMException("DCAM initialization failed with error code " + str(error_code))
CameraDevice.DCAMException: DCAM initialization failed with error code -2147483130

2019-12-03T09:54:03|CRITICAL|root|Unhandled exception:Traceback (most recent call last):
  File "C:\ProgramData\Anaconda3\lib\site-packages\ScopeFoundry\hardware.py", line 208, in enable_connection
    raise err
  File "C:\ProgramData\Anaconda3\lib\site-packages\ScopeFoundry\hardware.py", line 204, in enable_connection
    self.connect()
  File "C:\LabPrograms\Python\Hamamatsu_ScopeFoundry\CameraHardware.py", line 115, in connect
    binning = self.binning.val, hardware = self) #maybe with more cameras we have to change
  File "C:\LabPrograms\Python\Hamamatsu_ScopeFoundry\CameraDevice.py", line 336, in __init__
    raise DCAMException("DCAM initialization failed with error code " + str(error_code))
CameraDevice.DCAMException: DCAM initialization failed with error code -2147483130

