2019-02-08T14:47:30|CRITICAL|root|Unhandled exception:Traceback (most recent call last):
  File "C:\ProgramData\Anaconda3\lib\site-packages\ScopeFoundry\measurement.py", line 25, in run
    self.measurement._thread_run()
  File "C:\ProgramData\Anaconda3\lib\site-packages\ScopeFoundry\measurement.py", line 179, in _thread_run
    self.run()
  File "C:\Users\Admin\eclipse-workspace\Laser_DAQ_Camera\DaqControlledMeasurement.py", line 103, in run
    [frame, dims] = self.camera.hamamatsu.getLastFrame()
  File "C:\LabPrograms\Python\Camera-ScopeFoundry\CameraDevice.py", line 1101, in getLastFrame
    hc_data.copyData(paramlock.buf)
  File "C:\LabPrograms\Python\Camera-ScopeFoundry\CameraDevice.py", line 308, in copyData
    ctypes.memmove(self.np_array.ctypes.data, address, self.size) #copies self.size bytes from address into self.np_array.ctyps.data
OSError: exception: access violation reading 0x0000000000000000

