2019-02-14T13:07:34|CRITICAL|root|Unhandled exception:Traceback (most recent call last):
  File "C:\ProgramData\Anaconda3\lib\site-packages\ScopeFoundry\measurement.py", line 244, in start_stop
    self._start()
  File "C:\ProgramData\Anaconda3\lib\site-packages\ScopeFoundry\measurement.py", line 134, in _start
    raise RuntimeError("Cannot start a new measurement while still measuring")
RuntimeError: Cannot start a new measurement while still measuring

2019-02-14T13:12:06|CRITICAL|root|Unhandled exception:Traceback (most recent call last):
  File "C:\ProgramData\Anaconda3\lib\site-packages\ScopeFoundry\measurement.py", line 244, in start_stop
    self._start()
  File "C:\ProgramData\Anaconda3\lib\site-packages\ScopeFoundry\measurement.py", line 134, in _start
    raise RuntimeError("Cannot start a new measurement while still measuring")
RuntimeError: Cannot start a new measurement while still measuring

2019-02-14T13:33:15|CRITICAL|root|Unhandled exception:Traceback (most recent call last):
  File "C:\ProgramData\Anaconda3\lib\site-packages\ScopeFoundry\measurement.py", line 244, in start_stop
    self._start()
  File "C:\ProgramData\Anaconda3\lib\site-packages\ScopeFoundry\measurement.py", line 134, in _start
    raise RuntimeError("Cannot start a new measurement while still measuring")
RuntimeError: Cannot start a new measurement while still measuring

2019-02-14T13:35:22|CRITICAL|root|Unhandled exception:Traceback (most recent call last):
  File "C:\ProgramData\Anaconda3\lib\site-packages\ScopeFoundry\measurement.py", line 244, in start_stop
    self._start()
  File "C:\ProgramData\Anaconda3\lib\site-packages\ScopeFoundry\measurement.py", line 134, in _start
    raise RuntimeError("Cannot start a new measurement while still measuring")
RuntimeError: Cannot start a new measurement while still measuring

