2020-02-12T17:23:26|CRITICAL|root|Unhandled exception:Traceback (most recent call last):
  File "C:\ProgramData\Anaconda3\lib\site-packages\ScopeFoundry\hardware.py", line 208, in enable_connection
    raise err
  File "C:\ProgramData\Anaconda3\lib\site-packages\ScopeFoundry\hardware.py", line 204, in enable_connection
    self.connect()
  File "C:\LabPrograms\Python\laser\laser_hardware.py", line 35, in connect
    self.laser = LaserDevice(port=self.port.val, debug=self.debug_mode.val)
  File "C:\LabPrograms\Python\laser\laser_device.py", line 16, in __init__
    stopbits=1, xonxoff=False, timeout=3.0)
  File "C:\ProgramData\Anaconda3\lib\site-packages\serial\serialwin32.py", line 31, in __init__
    super(Serial, self).__init__(*args, **kwargs)
  File "C:\ProgramData\Anaconda3\lib\site-packages\serial\serialutil.py", line 240, in __init__
    self.open()
  File "C:\ProgramData\Anaconda3\lib\site-packages\serial\serialwin32.py", line 62, in open
    raise SerialException("could not open port {!r}: {!r}".format(self.portstr, ctypes.WinError()))
serial.serialutil.SerialException: could not open port 'COM7': PermissionError(13, 'Accesso negato.', None, 5)

2020-02-12T17:23:35|CRITICAL|root|Unhandled exception:Traceback (most recent call last):
  File "C:\ProgramData\Anaconda3\lib\site-packages\ScopeFoundry\measurement.py", line 25, in run
    self.measurement._thread_run()
  File "C:\ProgramData\Anaconda3\lib\site-packages\ScopeFoundry\measurement.py", line 179, in _thread_run
    self.run()
  File "C:\LabPrograms\Python\DAQ_Laser_Camera\SyncreadoutTriggerCounterMeasurement_dvp.py", line 55, in run
    self.initH5CellCounter()
  File "C:\LabPrograms\Python\DAQ_Laser_Camera\SyncreadoutTriggerCounterMeasurement_dvp.py", line 208, in initH5CellCounter
    dtype = "int16", chunks = (1,)
  File "C:\ProgramData\Anaconda3\lib\site-packages\h5py\_hl\group.py", line 116, in create_dataset
    dsid = dataset.make_new_dset(self, shape, dtype, data, **kwds)
  File "C:\ProgramData\Anaconda3\lib\site-packages\h5py\_hl\dataset.py", line 75, in make_new_dset
    shape = tuple(shape)
TypeError: 'int' object is not iterable

2020-02-12T17:23:35|CRITICAL|root|Unhandled exception:Traceback (most recent call last):
  File "C:\ProgramData\Anaconda3\lib\site-packages\pyqtgraph\graphicsItems\HistogramLUTItem.py", line 195, in imageChanged
    h = self.imageItem().getHistogram()
  File "C:\ProgramData\Anaconda3\lib\site-packages\pyqtgraph\graphicsItems\ImageItem.py", line 464, in getHistogram
    bins = np.arange(mn, mx+1.01*step, step, dtype=np.int)
ValueError: arange: cannot compute length

2020-02-12T17:23:35|CRITICAL|root|Unhandled exception:Traceback (most recent call last):
  File "C:\ProgramData\Anaconda3\lib\site-packages\pyqtgraph\graphicsItems\HistogramLUTItem.py", line 195, in imageChanged
    h = self.imageItem().getHistogram()
  File "C:\ProgramData\Anaconda3\lib\site-packages\pyqtgraph\graphicsItems\ImageItem.py", line 464, in getHistogram
    bins = np.arange(mn, mx+1.01*step, step, dtype=np.int)
ValueError: arange: cannot compute length

