2020-02-26T17:59:40|CRITICAL|root|Unhandled exception:Traceback (most recent call last):
  File "C:\ProgramData\Anaconda3\lib\site-packages\ScopeFoundry\measurement.py", line 25, in run
    self.measurement._thread_run()
  File "C:\ProgramData\Anaconda3\lib\site-packages\ScopeFoundry\measurement.py", line 179, in _thread_run
    self.run()
  File "C:\LabPrograms\Python\DAQ_Laser_Camera\Camera_dual_save_dvp.py", line 106, in run
    self.initH5CellCounter()
  File "C:\LabPrograms\Python\DAQ_Laser_Camera\Camera_dual_save_dvp.py", line 430, in initH5CellCounter
    self.h5file_counter = h5_io.h5_base_file(app=self.app, measurement=self)
  File "C:\ProgramData\Anaconda3\lib\site-packages\ScopeFoundry\h5_io.py", line 62, in h5_base_file
    ext='h5')
KeyError: 'sample'

2020-02-26T17:59:40|CRITICAL|root|Unhandled exception:Traceback (most recent call last):
  File "C:\ProgramData\Anaconda3\lib\site-packages\pyqtgraph\graphicsItems\HistogramLUTItem.py", line 195, in imageChanged
    h = self.imageItem().getHistogram()
  File "C:\ProgramData\Anaconda3\lib\site-packages\pyqtgraph\graphicsItems\ImageItem.py", line 464, in getHistogram
    bins = np.arange(mn, mx+1.01*step, step, dtype=np.int)
ValueError: arange: cannot compute length

2020-02-26T17:59:40|CRITICAL|root|Unhandled exception:Traceback (most recent call last):
  File "C:\ProgramData\Anaconda3\lib\site-packages\pyqtgraph\graphicsItems\HistogramLUTItem.py", line 195, in imageChanged
    h = self.imageItem().getHistogram()
  File "C:\ProgramData\Anaconda3\lib\site-packages\pyqtgraph\graphicsItems\ImageItem.py", line 464, in getHistogram
    bins = np.arange(mn, mx+1.01*step, step, dtype=np.int)
ValueError: arange: cannot compute length

