2020-09-21T10:11:36|CRITICAL|root|Unhandled exception:Traceback (most recent call last):
  File "C:\Users\Admin\anaconda3\envs\scopefoundry\lib\site-packages\ScopeFoundry\measurement.py", line 25, in run
    self.measurement._thread_run()
  File "C:\Users\Admin\anaconda3\envs\scopefoundry\lib\site-packages\ScopeFoundry\measurement.py", line 179, in _thread_run
    self.run()
  File "C:\LabPrograms\Python\PROCHIP_Microscope\PROCHIP_Measurement_cell_detection_MULTIROI.py", line 331, in run
    del self.roi_h5[check_pos]
IndexError: list assignment index out of range

