2020-08-07T17:47:51|CRITICAL|root|Unhandled exception:Traceback (most recent call last):
  File "C:\Users\Admin\anaconda3\envs\scopefoundry\lib\site-packages\ScopeFoundry\measurement.py", line 244, in start_stop
    self._start()
  File "C:\Users\Admin\anaconda3\envs\scopefoundry\lib\site-packages\ScopeFoundry\measurement.py", line 134, in _start
    raise RuntimeError("Cannot start a new measurement while still measuring")
RuntimeError: Cannot start a new measurement while still measuring

