2022-01-20T11:53:53|CRITICAL|root|Unhandled exception:Traceback (most recent call last):
  File "C:\Users\Admin\anaconda3\envs\scopefoundry\lib\site-packages\ScopeFoundry\hardware.py", line 208, in enable_connection
    raise err
  File "C:\Users\Admin\anaconda3\envs\scopefoundry\lib\site-packages\ScopeFoundry\hardware.py", line 204, in enable_connection
    self.connect()
  File "C:\LabPrograms\Python\OBIS_ScopeFoundry\laser_hardware.py", line 35, in connect
    self.laser = LaserDevice(port=self.port.val, debug=self.debug_mode.val)
  File "C:\LabPrograms\Python\OBIS_ScopeFoundry\laser_device.py", line 14, in __init__
    self.ser = ser = serial.Serial(port=self.port, baudrate=921600,
  File "C:\Users\Admin\anaconda3\envs\scopefoundry\lib\site-packages\serial\serialwin32.py", line 31, in __init__
    super(Serial, self).__init__(*args, **kwargs)
  File "C:\Users\Admin\anaconda3\envs\scopefoundry\lib\site-packages\serial\serialutil.py", line 240, in __init__
    self.open()
  File "C:\Users\Admin\anaconda3\envs\scopefoundry\lib\site-packages\serial\serialwin32.py", line 62, in open
    raise SerialException("could not open port {!r}: {!r}".format(self.portstr, ctypes.WinError()))
serial.serialutil.SerialException: could not open port 'COM6': FileNotFoundError(2, 'Impossibile trovare il file specificato.', None, 2)

2022-01-20T11:53:54|CRITICAL|root|Unhandled exception:Traceback (most recent call last):
  File "C:\Users\Admin\anaconda3\envs\scopefoundry\lib\site-packages\ScopeFoundry\hardware.py", line 208, in enable_connection
    raise err
  File "C:\Users\Admin\anaconda3\envs\scopefoundry\lib\site-packages\ScopeFoundry\hardware.py", line 204, in enable_connection
    self.connect()
  File "C:\LabPrograms\Python\OBIS_ScopeFoundry\laser_hardware.py", line 35, in connect
    self.laser = LaserDevice(port=self.port.val, debug=self.debug_mode.val)
  File "C:\LabPrograms\Python\OBIS_ScopeFoundry\laser_device.py", line 14, in __init__
    self.ser = ser = serial.Serial(port=self.port, baudrate=921600,
  File "C:\Users\Admin\anaconda3\envs\scopefoundry\lib\site-packages\serial\serialwin32.py", line 31, in __init__
    super(Serial, self).__init__(*args, **kwargs)
  File "C:\Users\Admin\anaconda3\envs\scopefoundry\lib\site-packages\serial\serialutil.py", line 240, in __init__
    self.open()
  File "C:\Users\Admin\anaconda3\envs\scopefoundry\lib\site-packages\serial\serialwin32.py", line 62, in open
    raise SerialException("could not open port {!r}: {!r}".format(self.portstr, ctypes.WinError()))
serial.serialutil.SerialException: could not open port 'COM7': FileNotFoundError(2, 'Impossibile trovare il file specificato.', None, 2)

2022-01-20T15:02:33|CRITICAL|root|Unhandled exception:Traceback (most recent call last):
  File "C:\LabPrograms\Python\HexSimAnalyser\HexSimAnalyser_measurement.py", line 433, in loadFile
    self.load_h5_file()
  File "C:\LabPrograms\Python\HexSimAnalyser\HexSimAnalyser_measurement.py", line 237, in load_h5_file
    available_datasets = self.open_PROCHIP_h5_file()
  File "C:\LabPrograms\Python\HexSimAnalyser\HexSimAnalyser_measurement.py", line 279, in open_PROCHIP_h5_file
    available_datasets = self.set_dataset(idx = 0)
  File "C:\LabPrograms\Python\HexSimAnalyser\HexSimAnalyser_measurement.py", line 314, in set_dataset
    self.imageRaw = stack
  File "C:\LabPrograms\Python\HexSimAnalyser\HexSimAnalyser_measurement.py", line 185, in imageRaw
    xcorr = self.calculate_carrier(img_raw[:,frame_index,:,:]) # calculates the power spectrum of imageRaw for the first phase
  File "C:\LabPrograms\Python\HexSimAnalyser\HexSimAnalyser_measurement.py", line 474, in calculate_carrier
    sum_prepared_comp[k, :, :] = sum_prepared_comp[k, :, :] + img[l, :, :] * M[k, l]
ValueError: operands could not be broadcast together with shapes (512,512) (512,700) 

2022-01-20T17:30:37|CRITICAL|root|Unhandled exception:Traceback (most recent call last):
  File "C:\LabPrograms\Python\HexSimAnalyser\HexSimAnalyser_measurement.py", line 31, in inner
    result = function(cls)
  File "C:\LabPrograms\Python\HexSimAnalyser\HexSimAnalyser_measurement.py", line 615, in standard_reconstruction
    self.imageSIM = self.h.reconstruct_rfftw(self.imageRaw[:,frame_index,:,:])
  File "C:\LabPrograms\Python\HexSimAnalyser\HexSimAnalyser_measurement.py", line 196, in imageSIM
    self.imvSIM.setImage(img_sim, autoRange=True, autoLevels=True, autoHistogramRange=True)
  File "C:\Users\Admin\anaconda3\envs\scopefoundry\lib\site-packages\pyqtgraph\imageview\ImageView.py", line 322, in setImage
    self.updateImage(autoHistogramRange=autoHistogramRange)
  File "C:\Users\Admin\anaconda3\envs\scopefoundry\lib\site-packages\pyqtgraph\imageview\ImageView.py", line 717, in updateImage
    self.ui.histogram.setHistogramRange(self.levelMin, self.levelMax)
  File "C:\Users\Admin\anaconda3\envs\scopefoundry\lib\site-packages\pyqtgraph\graphicsItems\HistogramLUTItem.py", line 155, in setHistogramRange
    self.vb.setYRange(mn, mx, padding)
  File "C:\Users\Admin\anaconda3\envs\scopefoundry\lib\site-packages\pyqtgraph\graphicsItems\ViewBox\ViewBox.py", line 649, in setYRange
    self.setRange(yRange=[min, max], update=update, padding=padding)
  File "C:\Users\Admin\anaconda3\envs\scopefoundry\lib\site-packages\pyqtgraph\graphicsItems\ViewBox\ViewBox.py", line 571, in setRange
    raise Exception("Cannot set range [%s, %s]" % (str(mn), str(mx)))
Exception: Cannot set range [nan, nan]

