2021-06-10T11:30:59|CRITICAL|root|Unhandled exception:Traceback (most recent call last):
  File "C:\Users\Admin\anaconda3\envs\scopefoundry\lib\site-packages\ScopeFoundry\hardware.py", line 208, in enable_connection
    raise err
  File "C:\Users\Admin\anaconda3\envs\scopefoundry\lib\site-packages\ScopeFoundry\hardware.py", line 204, in enable_connection
    self.connect()
  File "C:\LabPrograms\Python\OBIS_ScopeFoundry\laser_hardware.py", line 35, in connect
    self.laser = LaserDevice(port=self.port.val, debug=self.debug_mode.val)
  File "C:\LabPrograms\Python\OBIS_ScopeFoundry\laser_device.py", line 14, in __init__
    self.ser = ser = serial.Serial(port=self.port, baudrate=921600,
  File "C:\Users\Admin\anaconda3\envs\scopefoundry\lib\site-packages\serial\serialwin32.py", line 31, in __init__
    super(Serial, self).__init__(*args, **kwargs)
  File "C:\Users\Admin\anaconda3\envs\scopefoundry\lib\site-packages\serial\serialutil.py", line 240, in __init__
    self.open()
  File "C:\Users\Admin\anaconda3\envs\scopefoundry\lib\site-packages\serial\serialwin32.py", line 62, in open
    raise SerialException("could not open port {!r}: {!r}".format(self.portstr, ctypes.WinError()))
serial.serialutil.SerialException: could not open port 'COM6': PermissionError(13, 'Accesso negato.', None, 5)

2021-06-10T11:30:59|CRITICAL|root|Unhandled exception:Traceback (most recent call last):
  File "C:\Users\Admin\anaconda3\envs\scopefoundry\lib\site-packages\ScopeFoundry\hardware.py", line 208, in enable_connection
    raise err
  File "C:\Users\Admin\anaconda3\envs\scopefoundry\lib\site-packages\ScopeFoundry\hardware.py", line 204, in enable_connection
    self.connect()
  File "C:\LabPrograms\Python\OBIS_ScopeFoundry\laser_hardware.py", line 35, in connect
    self.laser = LaserDevice(port=self.port.val, debug=self.debug_mode.val)
  File "C:\LabPrograms\Python\OBIS_ScopeFoundry\laser_device.py", line 14, in __init__
    self.ser = ser = serial.Serial(port=self.port, baudrate=921600,
  File "C:\Users\Admin\anaconda3\envs\scopefoundry\lib\site-packages\serial\serialwin32.py", line 31, in __init__
    super(Serial, self).__init__(*args, **kwargs)
  File "C:\Users\Admin\anaconda3\envs\scopefoundry\lib\site-packages\serial\serialutil.py", line 240, in __init__
    self.open()
  File "C:\Users\Admin\anaconda3\envs\scopefoundry\lib\site-packages\serial\serialwin32.py", line 62, in open
    raise SerialException("could not open port {!r}: {!r}".format(self.portstr, ctypes.WinError()))
serial.serialutil.SerialException: could not open port 'COM7': FileNotFoundError(2, 'Impossibile trovare il file specificato.', None, 2)

2021-06-10T11:55:17|CRITICAL|root|Unhandled exception:Traceback (most recent call last):
  File "C:\Users\Admin\anaconda3\envs\scopefoundry\lib\site-packages\ScopeFoundry\measurement.py", line 25, in run
    self.measurement._thread_run()
  File "C:\Users\Admin\anaconda3\envs\scopefoundry\lib\site-packages\ScopeFoundry\measurement.py", line 179, in _thread_run
    self.run()
  File "C:\LabPrograms\Python\PROCHIP_Microscope\PROCHIP_Measurement_SIM.py", line 244, in run
    self.image_h5[ch_on_the_run][z_index[ch_on_the_run], :, :] = image_on_the_run  # saving to the h5 dataset
  File "h5py\_objects.pyx", line 54, in h5py._objects.with_phil.wrapper
  File "h5py\_objects.pyx", line 55, in h5py._objects.with_phil.wrapper
  File "C:\Users\Admin\anaconda3\envs\scopefoundry\lib\site-packages\h5py\_hl\dataset.py", line 685, in __setitem__
    selection = sel.select(self.shape, args, dsid=self.id)
  File "C:\Users\Admin\anaconda3\envs\scopefoundry\lib\site-packages\h5py\_hl\selections.py", line 94, in select
    sel[args]
  File "C:\Users\Admin\anaconda3\envs\scopefoundry\lib\site-packages\h5py\_hl\selections.py", line 261, in __getitem__
    start, count, step, scalar = _handle_simple(self.shape,args)
  File "C:\Users\Admin\anaconda3\envs\scopefoundry\lib\site-packages\h5py\_hl\selections.py", line 466, in _handle_simple
    x,y,z = _translate_int(int(arg), length)
  File "C:\Users\Admin\anaconda3\envs\scopefoundry\lib\site-packages\h5py\_hl\selections.py", line 486, in _translate_int
    raise ValueError("Index (%s) out of range (0-%s)" % (exp, length-1))
ValueError: Index (18) out of range (0-17)

2021-06-10T12:09:17|CRITICAL|root|Unhandled exception:Traceback (most recent call last):
  File "C:\Users\Admin\anaconda3\envs\scopefoundry\lib\site-packages\ScopeFoundry\measurement.py", line 25, in run
    self.measurement._thread_run()
  File "C:\Users\Admin\anaconda3\envs\scopefoundry\lib\site-packages\ScopeFoundry\measurement.py", line 179, in _thread_run
    self.run()
  File "C:\LabPrograms\Python\PROCHIP_Microscope\PROCHIP_Measurement_SIM.py", line 244, in run
    self.image_h5[ch_on_the_run][z_index[ch_on_the_run], :, :] = image_on_the_run  # saving to the h5 dataset
  File "h5py\_objects.pyx", line 54, in h5py._objects.with_phil.wrapper
  File "h5py\_objects.pyx", line 55, in h5py._objects.with_phil.wrapper
  File "C:\Users\Admin\anaconda3\envs\scopefoundry\lib\site-packages\h5py\_hl\dataset.py", line 685, in __setitem__
    selection = sel.select(self.shape, args, dsid=self.id)
  File "C:\Users\Admin\anaconda3\envs\scopefoundry\lib\site-packages\h5py\_hl\selections.py", line 94, in select
    sel[args]
  File "C:\Users\Admin\anaconda3\envs\scopefoundry\lib\site-packages\h5py\_hl\selections.py", line 261, in __getitem__
    start, count, step, scalar = _handle_simple(self.shape,args)
  File "C:\Users\Admin\anaconda3\envs\scopefoundry\lib\site-packages\h5py\_hl\selections.py", line 466, in _handle_simple
    x,y,z = _translate_int(int(arg), length)
  File "C:\Users\Admin\anaconda3\envs\scopefoundry\lib\site-packages\h5py\_hl\selections.py", line 486, in _translate_int
    raise ValueError("Index (%s) out of range (0-%s)" % (exp, length-1))
ValueError: Index (97) out of range (0-96)

