2021-11-24T09:37:29|CRITICAL|root|Unhandled exception:Traceback (most recent call last):
  File "C:\Users\Admin\anaconda3\envs\scopefoundry\lib\site-packages\ScopeFoundry\hardware.py", line 208, in enable_connection
    raise err
  File "C:\Users\Admin\anaconda3\envs\scopefoundry\lib\site-packages\ScopeFoundry\hardware.py", line 204, in enable_connection
    self.connect()
  File "C:\LabPrograms\Python\OBIS_ScopeFoundry\laser_hardware.py", line 35, in connect
    self.laser = LaserDevice(port=self.port.val, debug=self.debug_mode.val)
  File "C:\LabPrograms\Python\OBIS_ScopeFoundry\laser_device.py", line 14, in __init__
    self.ser = ser = serial.Serial(port=self.port, baudrate=921600,
  File "C:\Users\Admin\anaconda3\envs\scopefoundry\lib\site-packages\serial\serialwin32.py", line 31, in __init__
    super(Serial, self).__init__(*args, **kwargs)
  File "C:\Users\Admin\anaconda3\envs\scopefoundry\lib\site-packages\serial\serialutil.py", line 240, in __init__
    self.open()
  File "C:\Users\Admin\anaconda3\envs\scopefoundry\lib\site-packages\serial\serialwin32.py", line 62, in open
    raise SerialException("could not open port {!r}: {!r}".format(self.portstr, ctypes.WinError()))
serial.serialutil.SerialException: could not open port 'COM7': FileNotFoundError(2, 'Impossibile trovare il file specificato.', None, 2)

2021-11-24T09:50:59|CRITICAL|root|Unhandled exception:Traceback (most recent call last):
  File "C:\LabPrograms\Python\HexSimAnalyser\HexSimAnalyser_measurement.py", line 434, in loadFile
    self.load_h5_file()
  File "C:\LabPrograms\Python\HexSimAnalyser\HexSimAnalyser_measurement.py", line 238, in load_h5_file
    available_datasets = self.open_PROCHIP_h5_file()
  File "C:\LabPrograms\Python\HexSimAnalyser\HexSimAnalyser_measurement.py", line 280, in open_PROCHIP_h5_file
    available_datasets = self.set_dataset(idx = 0)
  File "C:\LabPrograms\Python\HexSimAnalyser\HexSimAnalyser_measurement.py", line 300, in set_dataset
    index_list, names = get_datasets_index_by_name(self.filename, t_idx)
  File "C:\LabPrograms\Python\HexSimAnalyser\get_h5_data.py", line 14, in get_datasets_index_by_name
    assert found > 0, "Specified h5 file does not exsist or have no datasets"
AssertionError: Specified h5 file does not exsist or have no datasets

