2021-05-26T18:47:37|CRITICAL|root|Unhandled exception:Traceback (most recent call last):
  File "C:\Users\Admin\anaconda3\envs\scopefoundry\lib\site-packages\ScopeFoundry\hardware.py", line 208, in enable_connection
    raise err
  File "C:\Users\Admin\anaconda3\envs\scopefoundry\lib\site-packages\ScopeFoundry\hardware.py", line 204, in enable_connection
    self.connect()
  File "C:\LabPrograms\Python\Hamamatsu_ScopeFoundry\CameraHardware.py", line 109, in connect
    self.hamamatsu = HamamatsuDevice(camera_id=0, frame_x=self.subarrayh.val, frame_y=self.subarrayv.val, acquisition_mode=self.acquisition_mode.val,
  File "C:\LabPrograms\Python\Hamamatsu_ScopeFoundry\CameraDevice.py", line 337, in __init__
    raise DCAMException("DCAM initialization failed with error code " + str(error_code))
Hamamatsu_ScopeFoundry.CameraDevice.DCAMException: DCAM initialization failed with error code -2147483130

2021-05-26T18:47:45|CRITICAL|root|Unhandled exception:Traceback (most recent call last):
  File "C:\Users\Admin\anaconda3\envs\scopefoundry\lib\site-packages\ScopeFoundry\hardware.py", line 208, in enable_connection
    raise err
  File "C:\Users\Admin\anaconda3\envs\scopefoundry\lib\site-packages\ScopeFoundry\hardware.py", line 204, in enable_connection
    self.connect()
  File "C:\LabPrograms\Python\OBIS_ScopeFoundry\laser_hardware.py", line 35, in connect
    self.laser = LaserDevice(port=self.port.val, debug=self.debug_mode.val)
  File "C:\LabPrograms\Python\OBIS_ScopeFoundry\laser_device.py", line 14, in __init__
    self.ser = ser = serial.Serial(port=self.port, baudrate=921600,
  File "C:\Users\Admin\anaconda3\envs\scopefoundry\lib\site-packages\serial\serialwin32.py", line 31, in __init__
    super(Serial, self).__init__(*args, **kwargs)
  File "C:\Users\Admin\anaconda3\envs\scopefoundry\lib\site-packages\serial\serialutil.py", line 240, in __init__
    self.open()
  File "C:\Users\Admin\anaconda3\envs\scopefoundry\lib\site-packages\serial\serialwin32.py", line 62, in open
    raise SerialException("could not open port {!r}: {!r}".format(self.portstr, ctypes.WinError()))
serial.serialutil.SerialException: could not open port 'COM6': PermissionError(13, 'Accesso negato.', None, 5)

2021-05-26T18:47:46|CRITICAL|root|Unhandled exception:Traceback (most recent call last):
  File "C:\Users\Admin\anaconda3\envs\scopefoundry\lib\site-packages\ScopeFoundry\hardware.py", line 208, in enable_connection
    raise err
  File "C:\Users\Admin\anaconda3\envs\scopefoundry\lib\site-packages\ScopeFoundry\hardware.py", line 204, in enable_connection
    self.connect()
  File "C:\LabPrograms\Python\OBIS_ScopeFoundry\laser_hardware.py", line 35, in connect
    self.laser = LaserDevice(port=self.port.val, debug=self.debug_mode.val)
  File "C:\LabPrograms\Python\OBIS_ScopeFoundry\laser_device.py", line 14, in __init__
    self.ser = ser = serial.Serial(port=self.port, baudrate=921600,
  File "C:\Users\Admin\anaconda3\envs\scopefoundry\lib\site-packages\serial\serialwin32.py", line 31, in __init__
    super(Serial, self).__init__(*args, **kwargs)
  File "C:\Users\Admin\anaconda3\envs\scopefoundry\lib\site-packages\serial\serialutil.py", line 240, in __init__
    self.open()
  File "C:\Users\Admin\anaconda3\envs\scopefoundry\lib\site-packages\serial\serialwin32.py", line 62, in open
    raise SerialException("could not open port {!r}: {!r}".format(self.portstr, ctypes.WinError()))
serial.serialutil.SerialException: could not open port 'COM7': PermissionError(13, 'Accesso negato.', None, 5)

2021-05-26T18:51:01|CRITICAL|root|Unhandled exception:Traceback (most recent call last):
  File "C:\LabPrograms\Python\PROCHIP_Microscope\PROCHIP_Measurement_multichannel.py", line 133, in run
    self.start_triggered_Acquisition(freq1)
  File "C:\LabPrograms\Python\PROCHIP_Microscope\PROCHIP_Measurement_multichannel.py", line 372, in start_triggered_Acquisition
    self.camera.hamamatsu.startAcquisition()
AttributeError: 'HamamatsuHardware' object has no attribute 'hamamatsu'

During handling of the above exception, another exception occurred:

Traceback (most recent call last):
  File "C:\Users\Admin\anaconda3\envs\scopefoundry\lib\site-packages\ScopeFoundry\measurement.py", line 25, in run
    self.measurement._thread_run()
  File "C:\Users\Admin\anaconda3\envs\scopefoundry\lib\site-packages\ScopeFoundry\measurement.py", line 179, in _thread_run
    self.run()
  File "C:\LabPrograms\Python\PROCHIP_Microscope\PROCHIP_Measurement_multichannel.py", line 249, in run
    self.stop_triggered_Acquisition()
  File "C:\LabPrograms\Python\PROCHIP_Microscope\PROCHIP_Measurement_multichannel.py", line 403, in stop_triggered_Acquisition
    self.camera.hamamatsu.stopAcquisition()
AttributeError: 'HamamatsuHardware' object has no attribute 'hamamatsu'

2021-05-26T18:51:06|CRITICAL|root|Unhandled exception:Traceback (most recent call last):
  File "C:\LabPrograms\Python\PROCHIP_Microscope\PROCHIP_Measurement_multichannel.py", line 133, in run
    self.start_triggered_Acquisition(freq1)
  File "C:\LabPrograms\Python\PROCHIP_Microscope\PROCHIP_Measurement_multichannel.py", line 372, in start_triggered_Acquisition
    self.camera.hamamatsu.startAcquisition()
AttributeError: 'HamamatsuHardware' object has no attribute 'hamamatsu'

During handling of the above exception, another exception occurred:

Traceback (most recent call last):
  File "C:\Users\Admin\anaconda3\envs\scopefoundry\lib\site-packages\ScopeFoundry\measurement.py", line 25, in run
    self.measurement._thread_run()
  File "C:\Users\Admin\anaconda3\envs\scopefoundry\lib\site-packages\ScopeFoundry\measurement.py", line 179, in _thread_run
    self.run()
  File "C:\LabPrograms\Python\PROCHIP_Microscope\PROCHIP_Measurement_multichannel.py", line 249, in run
    self.stop_triggered_Acquisition()
  File "C:\LabPrograms\Python\PROCHIP_Microscope\PROCHIP_Measurement_multichannel.py", line 403, in stop_triggered_Acquisition
    self.camera.hamamatsu.stopAcquisition()
AttributeError: 'HamamatsuHardware' object has no attribute 'hamamatsu'

2021-05-26T18:51:43|CRITICAL|root|Unhandled exception:Traceback (most recent call last):
  File "C:\LabPrograms\Python\PROCHIP_Microscope\PROCHIP_Measurement_multichannel.py", line 133, in run
    self.start_triggered_Acquisition(freq1)
  File "C:\LabPrograms\Python\PROCHIP_Microscope\PROCHIP_Measurement_multichannel.py", line 372, in start_triggered_Acquisition
    self.camera.hamamatsu.startAcquisition()
AttributeError: 'HamamatsuHardware' object has no attribute 'hamamatsu'

During handling of the above exception, another exception occurred:

Traceback (most recent call last):
  File "C:\Users\Admin\anaconda3\envs\scopefoundry\lib\site-packages\ScopeFoundry\measurement.py", line 25, in run
    self.measurement._thread_run()
  File "C:\Users\Admin\anaconda3\envs\scopefoundry\lib\site-packages\ScopeFoundry\measurement.py", line 179, in _thread_run
    self.run()
  File "C:\LabPrograms\Python\PROCHIP_Microscope\PROCHIP_Measurement_multichannel.py", line 249, in run
    self.stop_triggered_Acquisition()
  File "C:\LabPrograms\Python\PROCHIP_Microscope\PROCHIP_Measurement_multichannel.py", line 403, in stop_triggered_Acquisition
    self.camera.hamamatsu.stopAcquisition()
AttributeError: 'HamamatsuHardware' object has no attribute 'hamamatsu'

2021-05-26T18:52:02|CRITICAL|root|Unhandled exception:Traceback (most recent call last):
  File "C:\LabPrograms\Python\PROCHIP_Microscope\PROCHIP_Measurement_multichannel.py", line 133, in run
    self.start_triggered_Acquisition(freq1)
  File "C:\LabPrograms\Python\PROCHIP_Microscope\PROCHIP_Measurement_multichannel.py", line 372, in start_triggered_Acquisition
    self.camera.hamamatsu.startAcquisition()
AttributeError: 'HamamatsuHardware' object has no attribute 'hamamatsu'

During handling of the above exception, another exception occurred:

Traceback (most recent call last):
  File "C:\Users\Admin\anaconda3\envs\scopefoundry\lib\site-packages\ScopeFoundry\measurement.py", line 25, in run
    self.measurement._thread_run()
  File "C:\Users\Admin\anaconda3\envs\scopefoundry\lib\site-packages\ScopeFoundry\measurement.py", line 179, in _thread_run
    self.run()
  File "C:\LabPrograms\Python\PROCHIP_Microscope\PROCHIP_Measurement_multichannel.py", line 249, in run
    self.stop_triggered_Acquisition()
  File "C:\LabPrograms\Python\PROCHIP_Microscope\PROCHIP_Measurement_multichannel.py", line 403, in stop_triggered_Acquisition
    self.camera.hamamatsu.stopAcquisition()
AttributeError: 'HamamatsuHardware' object has no attribute 'hamamatsu'

2021-05-26T18:52:20|CRITICAL|root|Unhandled exception:Traceback (most recent call last):
  File "C:\LabPrograms\Python\PROCHIP_Microscope\PROCHIP_Measurement_multichannel.py", line 133, in run
    self.start_triggered_Acquisition(freq1)
  File "C:\LabPrograms\Python\PROCHIP_Microscope\PROCHIP_Measurement_multichannel.py", line 372, in start_triggered_Acquisition
    self.camera.hamamatsu.startAcquisition()
AttributeError: 'HamamatsuHardware' object has no attribute 'hamamatsu'

During handling of the above exception, another exception occurred:

Traceback (most recent call last):
  File "C:\Users\Admin\anaconda3\envs\scopefoundry\lib\site-packages\ScopeFoundry\measurement.py", line 25, in run
    self.measurement._thread_run()
  File "C:\Users\Admin\anaconda3\envs\scopefoundry\lib\site-packages\ScopeFoundry\measurement.py", line 179, in _thread_run
    self.run()
  File "C:\LabPrograms\Python\PROCHIP_Microscope\PROCHIP_Measurement_multichannel.py", line 249, in run
    self.stop_triggered_Acquisition()
  File "C:\LabPrograms\Python\PROCHIP_Microscope\PROCHIP_Measurement_multichannel.py", line 403, in stop_triggered_Acquisition
    self.camera.hamamatsu.stopAcquisition()
AttributeError: 'HamamatsuHardware' object has no attribute 'hamamatsu'

2021-05-26T18:52:23|CRITICAL|root|Unhandled exception:Traceback (most recent call last):
  File "C:\LabPrograms\Python\PROCHIP_Microscope\PROCHIP_Measurement_multichannel.py", line 133, in run
    self.start_triggered_Acquisition(freq1)
  File "C:\LabPrograms\Python\PROCHIP_Microscope\PROCHIP_Measurement_multichannel.py", line 372, in start_triggered_Acquisition
    self.camera.hamamatsu.startAcquisition()
AttributeError: 'HamamatsuHardware' object has no attribute 'hamamatsu'

During handling of the above exception, another exception occurred:

Traceback (most recent call last):
  File "C:\Users\Admin\anaconda3\envs\scopefoundry\lib\site-packages\ScopeFoundry\measurement.py", line 25, in run
    self.measurement._thread_run()
  File "C:\Users\Admin\anaconda3\envs\scopefoundry\lib\site-packages\ScopeFoundry\measurement.py", line 179, in _thread_run
    self.run()
  File "C:\LabPrograms\Python\PROCHIP_Microscope\PROCHIP_Measurement_multichannel.py", line 249, in run
    self.stop_triggered_Acquisition()
  File "C:\LabPrograms\Python\PROCHIP_Microscope\PROCHIP_Measurement_multichannel.py", line 403, in stop_triggered_Acquisition
    self.camera.hamamatsu.stopAcquisition()
AttributeError: 'HamamatsuHardware' object has no attribute 'hamamatsu'

2021-05-26T18:52:46|CRITICAL|root|Unhandled exception:Traceback (most recent call last):
  File "C:\Users\Admin\anaconda3\envs\scopefoundry\lib\site-packages\ScopeFoundry\hardware.py", line 208, in enable_connection
    raise err
  File "C:\Users\Admin\anaconda3\envs\scopefoundry\lib\site-packages\ScopeFoundry\hardware.py", line 204, in enable_connection
    self.connect()
  File "C:\LabPrograms\Python\Hamamatsu_ScopeFoundry\CameraHardware.py", line 109, in connect
    self.hamamatsu = HamamatsuDevice(camera_id=0, frame_x=self.subarrayh.val, frame_y=self.subarrayv.val, acquisition_mode=self.acquisition_mode.val,
  File "C:\LabPrograms\Python\Hamamatsu_ScopeFoundry\CameraDevice.py", line 337, in __init__
    raise DCAMException("DCAM initialization failed with error code " + str(error_code))
Hamamatsu_ScopeFoundry.CameraDevice.DCAMException: DCAM initialization failed with error code -2147483130

2021-05-26T18:53:52|CRITICAL|root|Unhandled exception:Traceback (most recent call last):
  File "C:\Users\Admin\anaconda3\envs\scopefoundry\lib\site-packages\ScopeFoundry\hardware.py", line 208, in enable_connection
    raise err
  File "C:\Users\Admin\anaconda3\envs\scopefoundry\lib\site-packages\ScopeFoundry\hardware.py", line 204, in enable_connection
    self.connect()
  File "C:\LabPrograms\Python\Hamamatsu_ScopeFoundry\CameraHardware.py", line 109, in connect
    self.hamamatsu = HamamatsuDevice(camera_id=0, frame_x=self.subarrayh.val, frame_y=self.subarrayv.val, acquisition_mode=self.acquisition_mode.val,
  File "C:\LabPrograms\Python\Hamamatsu_ScopeFoundry\CameraDevice.py", line 337, in __init__
    raise DCAMException("DCAM initialization failed with error code " + str(error_code))
Hamamatsu_ScopeFoundry.CameraDevice.DCAMException: DCAM initialization failed with error code -2147483130

2021-05-26T18:54:21|CRITICAL|root|Unhandled exception:Traceback (most recent call last):
  File "C:\LabPrograms\Python\Hamamatsu_ScopeFoundry\CameraMeasurement.py", line 106, in run
    self.camera.hamamatsu.startAcquisition()
AttributeError: 'HamamatsuHardware' object has no attribute 'hamamatsu'

During handling of the above exception, another exception occurred:

Traceback (most recent call last):
  File "C:\Users\Admin\anaconda3\envs\scopefoundry\lib\site-packages\ScopeFoundry\measurement.py", line 25, in run
    self.measurement._thread_run()
  File "C:\Users\Admin\anaconda3\envs\scopefoundry\lib\site-packages\ScopeFoundry\measurement.py", line 179, in _thread_run
    self.run()
  File "C:\LabPrograms\Python\Hamamatsu_ScopeFoundry\CameraMeasurement.py", line 198, in run
    self.camera.hamamatsu.stopAcquisition()
AttributeError: 'HamamatsuHardware' object has no attribute 'hamamatsu'

2021-05-26T18:54:24|CRITICAL|root|Unhandled exception:Traceback (most recent call last):
  File "C:\Users\Admin\anaconda3\envs\scopefoundry\lib\site-packages\ScopeFoundry\hardware.py", line 208, in enable_connection
    raise err
  File "C:\Users\Admin\anaconda3\envs\scopefoundry\lib\site-packages\ScopeFoundry\hardware.py", line 204, in enable_connection
    self.connect()
  File "C:\LabPrograms\Python\Hamamatsu_ScopeFoundry\CameraHardware.py", line 109, in connect
    self.hamamatsu = HamamatsuDevice(camera_id=0, frame_x=self.subarrayh.val, frame_y=self.subarrayv.val, acquisition_mode=self.acquisition_mode.val,
  File "C:\LabPrograms\Python\Hamamatsu_ScopeFoundry\CameraDevice.py", line 337, in __init__
    raise DCAMException("DCAM initialization failed with error code " + str(error_code))
Hamamatsu_ScopeFoundry.CameraDevice.DCAMException: DCAM initialization failed with error code -2147483130

2021-05-26T18:54:59|CRITICAL|root|Unhandled exception:Traceback (most recent call last):
  File "C:\Users\Admin\anaconda3\envs\scopefoundry\lib\site-packages\ScopeFoundry\hardware.py", line 208, in enable_connection
    raise err
  File "C:\Users\Admin\anaconda3\envs\scopefoundry\lib\site-packages\ScopeFoundry\hardware.py", line 204, in enable_connection
    self.connect()
  File "C:\LabPrograms\Python\Hamamatsu_ScopeFoundry\CameraHardware.py", line 109, in connect
    self.hamamatsu = HamamatsuDevice(camera_id=0, frame_x=self.subarrayh.val, frame_y=self.subarrayv.val, acquisition_mode=self.acquisition_mode.val,
  File "C:\LabPrograms\Python\Hamamatsu_ScopeFoundry\CameraDevice.py", line 337, in __init__
    raise DCAMException("DCAM initialization failed with error code " + str(error_code))
Hamamatsu_ScopeFoundry.CameraDevice.DCAMException: DCAM initialization failed with error code -2147483130

