2021-09-27T10:38:49|CRITICAL|root|Unhandled exception:Traceback (most recent call last):
  File "C:\Users\Admin\anaconda3\envs\scopefoundry\lib\site-packages\ScopeFoundry\hardware.py", line 208, in enable_connection
    raise err
  File "C:\Users\Admin\anaconda3\envs\scopefoundry\lib\site-packages\ScopeFoundry\hardware.py", line 204, in enable_connection
    self.connect()
  File "C:\LabPrograms\Python\Hamamatsu_ScopeFoundry\CameraHardware.py", line 109, in connect
    self.hamamatsu = HamamatsuDevice(camera_id=0, frame_x=self.subarrayh.val, frame_y=self.subarrayv.val, acquisition_mode=self.acquisition_mode.val,
  File "C:\LabPrograms\Python\Hamamatsu_ScopeFoundry\CameraDevice.py", line 337, in __init__
    raise DCAMException("DCAM initialization failed with error code " + str(error_code))
Hamamatsu_ScopeFoundry.CameraDevice.DCAMException: DCAM initialization failed with error code -2147483130

2021-09-27T10:38:51|CRITICAL|root|Unhandled exception:Traceback (most recent call last):
  File "C:\Users\Admin\anaconda3\envs\scopefoundry\lib\site-packages\ScopeFoundry\hardware.py", line 208, in enable_connection
    raise err
  File "C:\Users\Admin\anaconda3\envs\scopefoundry\lib\site-packages\ScopeFoundry\hardware.py", line 204, in enable_connection
    self.connect()
  File "C:\LabPrograms\Python\OBIS_ScopeFoundry\laser_hardware.py", line 35, in connect
    self.laser = LaserDevice(port=self.port.val, debug=self.debug_mode.val)
  File "C:\LabPrograms\Python\OBIS_ScopeFoundry\laser_device.py", line 14, in __init__
    self.ser = ser = serial.Serial(port=self.port, baudrate=921600,
  File "C:\Users\Admin\anaconda3\envs\scopefoundry\lib\site-packages\serial\serialwin32.py", line 31, in __init__
    super(Serial, self).__init__(*args, **kwargs)
  File "C:\Users\Admin\anaconda3\envs\scopefoundry\lib\site-packages\serial\serialutil.py", line 240, in __init__
    self.open()
  File "C:\Users\Admin\anaconda3\envs\scopefoundry\lib\site-packages\serial\serialwin32.py", line 62, in open
    raise SerialException("could not open port {!r}: {!r}".format(self.portstr, ctypes.WinError()))
serial.serialutil.SerialException: could not open port 'COM6': FileNotFoundError(2, 'Impossibile trovare il file specificato.', None, 2)

2021-09-27T10:38:52|CRITICAL|root|Unhandled exception:Traceback (most recent call last):
  File "C:\Users\Admin\anaconda3\envs\scopefoundry\lib\site-packages\ScopeFoundry\hardware.py", line 208, in enable_connection
    raise err
  File "C:\Users\Admin\anaconda3\envs\scopefoundry\lib\site-packages\ScopeFoundry\hardware.py", line 204, in enable_connection
    self.connect()
  File "C:\LabPrograms\Python\OBIS_ScopeFoundry\laser_hardware.py", line 35, in connect
    self.laser = LaserDevice(port=self.port.val, debug=self.debug_mode.val)
  File "C:\LabPrograms\Python\OBIS_ScopeFoundry\laser_device.py", line 14, in __init__
    self.ser = ser = serial.Serial(port=self.port, baudrate=921600,
  File "C:\Users\Admin\anaconda3\envs\scopefoundry\lib\site-packages\serial\serialwin32.py", line 31, in __init__
    super(Serial, self).__init__(*args, **kwargs)
  File "C:\Users\Admin\anaconda3\envs\scopefoundry\lib\site-packages\serial\serialutil.py", line 240, in __init__
    self.open()
  File "C:\Users\Admin\anaconda3\envs\scopefoundry\lib\site-packages\serial\serialwin32.py", line 62, in open
    raise SerialException("could not open port {!r}: {!r}".format(self.portstr, ctypes.WinError()))
serial.serialutil.SerialException: could not open port 'COM7': FileNotFoundError(2, 'Impossibile trovare il file specificato.', None, 2)

2021-09-27T10:56:07|CRITICAL|root|Unhandled exception:Traceback (most recent call last):
  File "C:\LabPrograms\Python\PROCHIP_Microscope\PROCHIP_Measurement_cell_detection_SINGLE_COLOR.py", line 112, in run
    self.start_Acquisition()
  File "C:\LabPrograms\Python\PROCHIP_Microscope\PROCHIP_Measurement_cell_detection_SINGLE_COLOR.py", line 320, in start_Acquisition
    self.camera.hamamatsu.startAcquisition()
AttributeError: 'HamamatsuHardware' object has no attribute 'hamamatsu'

During handling of the above exception, another exception occurred:

Traceback (most recent call last):
  File "C:\Users\Admin\anaconda3\envs\scopefoundry\lib\site-packages\ScopeFoundry\measurement.py", line 25, in run
    self.measurement._thread_run()
  File "C:\Users\Admin\anaconda3\envs\scopefoundry\lib\site-packages\ScopeFoundry\measurement.py", line 179, in _thread_run
    self.run()
  File "C:\LabPrograms\Python\PROCHIP_Microscope\PROCHIP_Measurement_cell_detection_SINGLE_COLOR.py", line 228, in run
    self.stop_Acquisition()
  File "C:\LabPrograms\Python\PROCHIP_Microscope\PROCHIP_Measurement_cell_detection_SINGLE_COLOR.py", line 337, in stop_Acquisition
    self.camera.hamamatsu.stopAcquisition()
AttributeError: 'HamamatsuHardware' object has no attribute 'hamamatsu'

